2022-07-12 19:15:53,940 INFO    MainThread:10892 [internal.py:wandb_internal():90] W&B internal server running at pid: 10892, started at: 2022-07-12 19:15:53.939278
2022-07-12 19:15:53,944 INFO    WriterThread:10892 [datastore.py:open_for_write():75] open: C:\Users\cosmi\Documents\Mannheim\ines-autonomous-dispatching\wandb\run-20220712_191551-3hlzt0j5\run-3hlzt0j5.wandb
2022-07-12 19:15:53,951 DEBUG   SenderThread:10892 [sender.py:send():235] send: header
2022-07-12 19:15:53,951 DEBUG   SenderThread:10892 [sender.py:send():235] send: run
2022-07-12 19:15:57,236 ERROR   SenderThread:10892 [retry.py:__call__():132] Retry attempt failed:
Traceback (most recent call last):
  File "C:\Users\cosmi\anaconda3\envs\teamproject\lib\site-packages\urllib3\connection.py", line 174, in _new_conn
    conn = connection.create_connection(
  File "C:\Users\cosmi\anaconda3\envs\teamproject\lib\site-packages\urllib3\util\connection.py", line 72, in create_connection
    for res in socket.getaddrinfo(host, port, family, socket.SOCK_STREAM):
  File "C:\Users\cosmi\anaconda3\envs\teamproject\lib\socket.py", line 954, in getaddrinfo
    for res in _socket.getaddrinfo(host, port, family, type, proto, flags):
socket.gaierror: [Errno 11001] getaddrinfo failed

During handling of the above exception, another exception occurred:

Traceback (most recent call last):
  File "C:\Users\cosmi\anaconda3\envs\teamproject\lib\site-packages\urllib3\connectionpool.py", line 703, in urlopen
    httplib_response = self._make_request(
  File "C:\Users\cosmi\anaconda3\envs\teamproject\lib\site-packages\urllib3\connectionpool.py", line 386, in _make_request
    self._validate_conn(conn)
  File "C:\Users\cosmi\anaconda3\envs\teamproject\lib\site-packages\urllib3\connectionpool.py", line 1040, in _validate_conn
    conn.connect()
  File "C:\Users\cosmi\anaconda3\envs\teamproject\lib\site-packages\urllib3\connection.py", line 358, in connect
    self.sock = conn = self._new_conn()
  File "C:\Users\cosmi\anaconda3\envs\teamproject\lib\site-packages\urllib3\connection.py", line 186, in _new_conn
    raise NewConnectionError(
urllib3.exceptions.NewConnectionError: <urllib3.connection.HTTPSConnection object at 0x000001C9C23192B0>: Failed to establish a new connection: [Errno 11001] getaddrinfo failed

During handling of the above exception, another exception occurred:

Traceback (most recent call last):
  File "C:\Users\cosmi\anaconda3\envs\teamproject\lib\site-packages\requests\adapters.py", line 489, in send
    resp = conn.urlopen(
  File "C:\Users\cosmi\anaconda3\envs\teamproject\lib\site-packages\urllib3\connectionpool.py", line 785, in urlopen
    retries = retries.increment(
  File "C:\Users\cosmi\anaconda3\envs\teamproject\lib\site-packages\urllib3\util\retry.py", line 592, in increment
    raise MaxRetryError(_pool, url, error or ResponseError(cause))
urllib3.exceptions.MaxRetryError: HTTPSConnectionPool(host='api.wandb.ai', port=443): Max retries exceeded with url: /graphql (Caused by NewConnectionError('<urllib3.connection.HTTPSConnection object at 0x000001C9C23192B0>: Failed to establish a new connection: [Errno 11001] getaddrinfo failed'))

During handling of the above exception, another exception occurred:

Traceback (most recent call last):
  File "C:\Users\cosmi\anaconda3\envs\teamproject\lib\site-packages\wandb\sdk\lib\retry.py", line 108, in __call__
    result = self._call_fn(*args, **kwargs)
  File "C:\Users\cosmi\anaconda3\envs\teamproject\lib\site-packages\wandb\sdk\internal\internal_api.py", line 140, in execute
    return self.client.execute(*args, **kwargs)
  File "C:\Users\cosmi\anaconda3\envs\teamproject\lib\site-packages\wandb\vendor\gql-0.2.0\wandb_gql\client.py", line 52, in execute
    result = self._get_result(document, *args, **kwargs)
  File "C:\Users\cosmi\anaconda3\envs\teamproject\lib\site-packages\wandb\vendor\gql-0.2.0\wandb_gql\client.py", line 60, in _get_result
    return self.transport.execute(document, *args, **kwargs)
  File "C:\Users\cosmi\anaconda3\envs\teamproject\lib\site-packages\wandb\vendor\gql-0.2.0\wandb_gql\transport\requests.py", line 38, in execute
    request = requests.post(self.url, **post_args)
  File "C:\Users\cosmi\anaconda3\envs\teamproject\lib\site-packages\requests\api.py", line 115, in post
    return request("post", url, data=data, json=json, **kwargs)
  File "C:\Users\cosmi\anaconda3\envs\teamproject\lib\site-packages\requests\api.py", line 59, in request
    return session.request(method=method, url=url, **kwargs)
  File "C:\Users\cosmi\anaconda3\envs\teamproject\lib\site-packages\requests\sessions.py", line 587, in request
    resp = self.send(prep, **send_kwargs)
  File "C:\Users\cosmi\anaconda3\envs\teamproject\lib\site-packages\requests\sessions.py", line 701, in send
    r = adapter.send(request, **kwargs)
  File "C:\Users\cosmi\anaconda3\envs\teamproject\lib\site-packages\requests\adapters.py", line 565, in send
    raise ConnectionError(e, request=request)
requests.exceptions.ConnectionError: HTTPSConnectionPool(host='api.wandb.ai', port=443): Max retries exceeded with url: /graphql (Caused by NewConnectionError('<urllib3.connection.HTTPSConnection object at 0x000001C9C23192B0>: Failed to establish a new connection: [Errno 11001] getaddrinfo failed'))
2022-07-12 19:16:22,034 DEBUG   HandlerThread:10892 [handler.py:handle_request():141] handle_request: shutdown
2022-07-12 19:16:22,036 INFO    HandlerThread:10892 [handler.py:finish():806] shutting down handler
2022-07-12 19:16:22,140 INFO    WriterThread:10892 [datastore.py:close():279] close: C:\Users\cosmi\Documents\Mannheim\ines-autonomous-dispatching\wandb\run-20220712_191551-3hlzt0j5\run-3hlzt0j5.wandb
2022-07-12 19:16:29,780 INFO    SenderThread:10892 [dir_watcher.py:__init__():205] watching files in: C:\Users\cosmi\Documents\Mannheim\ines-autonomous-dispatching\wandb\run-20220712_191551-3hlzt0j5\files
2022-07-12 19:16:29,780 INFO    SenderThread:10892 [sender.py:_start_run_threads():812] run started: 3hlzt0j5 with start time 1657642551
2022-07-12 19:16:29,780 INFO    SenderThread:10892 [sender.py:finish():1111] shutting down sender
2022-07-12 19:16:29,780 INFO    SenderThread:10892 [dir_watcher.py:finish():336] shutting down directory watcher
2022-07-12 19:16:30,787 INFO    SenderThread:10892 [dir_watcher.py:finish():366] scan: C:\Users\cosmi\Documents\Mannheim\ines-autonomous-dispatching\wandb\run-20220712_191551-3hlzt0j5\files
2022-07-12 19:16:30,788 INFO    SenderThread:10892 [dir_watcher.py:finish():380] scan save: C:\Users\cosmi\Documents\Mannheim\ines-autonomous-dispatching\wandb\run-20220712_191551-3hlzt0j5\files\config.yaml config.yaml
2022-07-12 19:16:30,789 INFO    SenderThread:10892 [file_pusher.py:finish():145] shutting down file pusher
2022-07-12 19:16:30,789 INFO    SenderThread:10892 [file_pusher.py:join():150] waiting for file pusher
2022-07-12 19:16:31,729 INFO    Thread-13 :10892 [upload_job.py:push():132] Uploaded file C:\Users\cosmi\Documents\Mannheim\ines-autonomous-dispatching\wandb\run-20220712_191551-3hlzt0j5\files\config.yaml
2022-07-12 19:16:32,827 INFO    MainThread:10892 [internal.py:handle_exit():80] Internal process exited
